<?xml version="1.0" ?>
<robot name="robot" xmlns:xacro="http://www.ros.org/wiki/xacro">

<xacro:include filename="$(find robot_description)/urdf/materials.xacro" />
<xacro:include filename="$(find robot_description)/urdf/robot.trans" />
<xacro:include filename="$(find robot_description)/urdf/robot.gazebo" />


<gazebo>
  <plugin name="gazebo_ros_control" filename="libgazebo_ros_control.so">
    <robotNamespace>/</robotNamespace>
  </plugin>
</gazebo>



<link name="world"/>
<joint name="base_joint" type="fixed">
<parent link="world"/>
<child link="base_link"/>
<origin rpy="0 0 0" xyz="0.0 0.0 0.17"/>
</joint>

<link name="base_link">
  <inertial>
    <origin xyz="0.005160276109435298 0.0027084129987447227 0.026026914877480482" rpy="0 0.2 0"/>
    <mass value="0.7428696086251847"/>
    <inertia ixx="0.001021" iyy="0.001049" izz="0.001616" ixy="-2e-05" iyz="7e-06" ixz="7e-06"/>
  </inertial>
  <visual>
    <origin xyz="0 0 0" rpy="0 0 0"/>
    <geometry>
      <mesh filename="package://robot_description/meshes/base_link.stl" scale="0.001 0.001 0.001"/>
    </geometry>
    <material name="silver"/>
  </visual>
  <collision>
    <origin xyz="0 0 0" rpy="0 0 0"/>
    <geometry>
      <mesh filename="package://robot_description/meshes/base_link.stl" scale="0.001 0.001 0.001"/>
    </geometry>
  </collision>
</link>

<link name="Arm_02.step_1">
  <inertial>
    <origin xyz="-0.003592446758183772 -0.014135752925911696 0.0394951780060995" rpy="0 0.2 0"/>
    <mass value="0.3697152157519886"/>
    <inertia ixx="0.000407" iyy="0.000389" izz="0.000105" ixy="-3e-05" iyz="8.1e-05" ixz="6.6e-05"/>
  </inertial>
  <visual>
    <origin xyz="-0.055174 -0.076664 -0.191534" rpy="0 0 0"/>
    <geometry>
      <mesh filename="package://robot_description/meshes/Arm_02.step_1.stl" scale="0.001 0.001 0.001"/>
    </geometry>
    <material name="silver"/>
  </visual>
  <collision>
    <origin xyz="-0.055174 -0.076664 -0.191534" rpy="0 0 0"/>
    <geometry>
      <mesh filename="package://robot_description/meshes/Arm_02.step_1.stl" scale="0.001 0.001 0.001"/>
    </geometry>
  </collision>
</link>

<link name="Arm_03.step_1">
  <inertial>
    <origin xyz="-0.008471262397111417 -0.00952529589921284 0.014418181004394182" rpy="0 0.2 0"/>
    <mass value="0.12929190705351673"/>
    <inertia ixx="3e-05" iyy="3.6e-05" izz="2.4e-05" ixy="-1e-06" iyz="9e-06" ixz="2e-06"/>
  </inertial>
  <visual>
    <origin xyz="-0.038998 -0.045832 -0.274607" rpy="0 0 0"/>
    <geometry>
      <mesh filename="package://robot_description/meshes/Arm_03.step_1.stl" scale="0.001 0.001 0.001"/>
    </geometry>
    <material name="silver"/>
  </visual>
  <collision>
    <origin xyz="-0.038998 -0.045832 -0.274607" rpy="0 0 0"/>
    <geometry>
      <mesh filename="package://robot_description/meshes/Arm_03.step_1.stl" scale="0.001 0.001 0.001"/>
    </geometry>
  </collision>
</link>

<link name="Part_2_gear_2.step_1">
  <inertial>
    <origin xyz="-0.0019345128307690623 -0.005439855470670305 0.00023644869023009552" rpy="0 0 0"/>
    <mass value="0.020866715753086653"/>
    <inertia ixx="4e-06" iyy="1e-06" izz="3e-06" ixy="0.0" iyz="-0.0" ixz="-0.0"/>
  </inertial>
  <visual>
    <origin xyz="-0.015316 -0.006244 -0.330746" rpy="0 0 0"/>
    <geometry>
      <mesh filename="package://robot_description/meshes/Part_2_gear_2.step_1.stl" scale="0.001 0.001 0.001"/>
    </geometry>
    <material name="silver"/>
  </visual>
  <collision>
    <origin xyz="-0.015316 -0.006244 -0.330746" rpy="0 0 0"/>
    <geometry>
      <mesh filename="package://robot_description/meshes/Part_2_gear_2.step_1.stl" scale="0.001 0.001 0.001"/>
    </geometry>
  </collision>
</link>





<link name="Gripper_Base.step_1">
  <inertial>
    <origin xyz="-0.006039901919946484 -0.0027152948165855076 0.025224632891133025" rpy="0 0 0"/>
    <mass value="0.1259188443483361"/>
    <inertia ixx="7.1e-05" iyy="6.2e-05" izz="2.1e-05" ixy="0.0" iyz="-4e-06" ixz="1e-05"/>
  </inertial>
  <visual>
    <origin xyz="-0.028594 -0.025213 -0.296325" rpy="0 0 0"/>
    <geometry>
      <mesh filename="package://robot_description/meshes/Gripper_Base.step_1.stl" scale="0.001 0.001 0.001"/>
    </geometry>
    <material name="silver"/>
  </visual>
  <collision>
    <origin xyz="-0.028594 -0.025213 -0.296325" rpy="0 0 0"/>
    <geometry>
      <mesh filename="package://robot_description/meshes/Gripper_Base.step_1.stl" scale="0.001 0.001 0.001"/>
    </geometry>
  </collision>
</link>

<link name="Servo_motor_micro_9g.step_1">
  <inertial>
    <origin xyz="0.014115900275686065 0.004671900820636288 0.0010411024196047558" rpy="0 0 0"/>
    <mass value="0.05634268516919814"/>
    <inertia ixx="3e-06" iyy="4e-06" izz="5e-06" ixy="-0.0" iyz="-1e-06" ixz="-0.0"/>
  </inertial>
  <visual>
    <origin xyz="-0.015122 -0.032168 -0.337924" rpy="0 0 0"/>
    <geometry>
      <mesh filename="package://robot_description/meshes/Servo_motor_micro_9g.step_1.stl" scale="0.001 0.001 0.001"/>
    </geometry>
    <material name="silver"/>
  </visual>
  <collision>
    <origin xyz="-0.015122 -0.032168 -0.337924" rpy="0 0 0"/>
    <geometry>
      <mesh filename="package://robot_description/meshes/Servo_motor_micro_9g.step_1.stl" scale="0.001 0.001 0.001"/>
    </geometry>
  </collision>
</link>

<link name="Part_1_gear_2.step_1">
  <inertial>
    <origin xyz="-0.0019952182319104145 0.0042041364935786404 0.0036744285304463054" rpy="0 0 0"/>
    <mass value="0.020267194631427798"/>
    <inertia ixx="4e-06" iyy="1e-06" izz="2e-06" ixy="0.0" iyz="-1e-06" ixz="-0.0"/>
  </inertial>
  <visual>
    <origin xyz="-0.015122 -0.032168 -0.337924" rpy="0 0 0"/>
    <geometry>
      <mesh filename="package://robot_description/meshes/Part_1_gear_2.step_1.stl" scale="0.001 0.001 0.001"/>
    </geometry>
    <material name="silver"/>
  </visual>
  <collision>
    <origin xyz="-0.015122 -0.032168 -0.337924" rpy="0 0 0"/>
    <geometry>
      <mesh filename="package://robot_description/meshes/Part_1_gear_2.step_1.stl" scale="0.001 0.001 0.001"/>
    </geometry>
  </collision>
</link>







<link name="robot_Gripper.step1_v1_1">
  <inertial>
    <origin xyz="0.002340459323116762 -0.002989299603796597 0.003797449185666102" rpy="0 0 0"/>
    <mass value="0.020053604711887"/>
    <inertia ixx="6e-06" iyy="6e-06" izz="0.0" ixy="0.0" iyz="1e-06" ixz="-0.0"/>
  </inertial>
  <visual>
    <origin xyz="-0.015937 0.02234 -0.350609" rpy="0 0 0"/>
    <geometry>
      <mesh filename="package://robot_description/meshes/robot_Gripper.step1_v1_1.stl" scale="0.001 0.001 0.001"/>
    </geometry>
    <material name="silver"/>
  </visual>
  <collision>
    <origin xyz="-0.015937 0.02234 -0.350609" rpy="0 0 0"/>
    <geometry>
      <mesh filename="package://robot_description/meshes/robot_Gripper.step1_v1_1.stl" scale="0.001 0.001 0.001"/>
    </geometry>
  </collision>
</link>

<link name="Waist.step_1">
  <inertial>
    <origin xyz="0.006414134056216764 -0.003189639915015318 0.01955990648290272" rpy="0 0 0"/>
    <mass value="0.5781357922590845"/>
    <inertia ixx="0.000493" iyy="0.00044" izz="0.000467" ixy="-6.4e-05" iyz="-1.8e-05" ixz="-7.1e-05"/>
  </inertial>
  <visual>
    <origin xyz="-0.003126 -0.001866 -0.059863" rpy="0 0 0"/>
    <geometry>
      <mesh filename="package://robot_description/meshes/Waist.step_1.stl" scale="0.001 0.001 0.001"/>
    </geometry>
    <material name="silver"/>
  </visual>
  <collision>
    <origin xyz="-0.003126 -0.001866 -0.059863" rpy="0 0 0"/>
    <geometry>
      <mesh filename="package://robot_description/meshes/Waist.step_1.stl" scale="0.001 0.001 0.001"/>
    </geometry>
  </collision>
</link>

<link name="Arm_01.step_1">
  <inertial>
    <origin xyz="0.01466432189256404 0.03730233924473003 0.0453548332023245" rpy="0 0 0"/>
    <mass value="0.5035804638838921"/>
    <inertia ixx="0.000749" iyy="0.000603" izz="0.000388" ixy="-0.000161" iyz="-0.00031" ixz="-0.000197"/>
  </inertial>
  <visual>
    <origin xyz="-0.012969 -0.010778 -0.100553" rpy="0 0 0"/>
    <geometry>
      <mesh filename="package://robot_description/meshes/Arm_01.step_1.stl" scale="0.001 0.001 0.001"/>
    </geometry>
    <material name="silver"/>
  </visual>
  <collision>
    <origin xyz="-0.012969 -0.010778 -0.100553" rpy="0 0 0"/>
    <geometry>
      <mesh filename="package://robot_description/meshes/Arm_01.step_1.stl" scale="0.001 0.001 0.001"/>
    </geometry>
  </collision>
</link>


<link name="Gripper.step_1">
  <inertial>
    <origin xyz="0.0023163136457740787 0.00044229427431653756 0.004823903757310233" rpy="0 0 0"/>
    <mass value="0.02005360471188671"/>
    <inertia ixx="6e-06" iyy="5e-06" izz="1e-06" ixy="0.0" iyz="2e-06" ixz="-0.0"/>
  </inertial>
  <visual>
    <origin xyz="-0.015498 -0.043643 -0.372614" rpy="0 0 0"/>
    <geometry>
      <mesh filename="package://robot_description/meshes/Gripper.step_1.stl" scale="0.001 0.001 0.001"/>
    </geometry>
    <material name="silver"/>
  </visual>
  <collision>
    <origin xyz="-0.015498 -0.043643 -0.372614" rpy="0 0 0"/>
    <geometry>
      <mesh filename="package://robot_description/meshes/Gripper.step_1.stl" scale="0.001 0.001 0.001"/>
    </geometry>
  </collision>
</link>

<joint name="Revolute_4" type="revolute">
  <origin xyz="0.042205 0.065886 0.090981" rpy="0 0 0"/>
  <parent link="Arm_01.step_1"/>
  <child link="Arm_02.step_1"/>
  <axis xyz="-0.828979 0.558915 -0.020195"/>
  <limit upper="3.141593" lower="0.0" effort="100" velocity="100"/>
</joint>

<joint name="Revolute_5" type="revolute">
  <origin xyz="-0.016176 -0.030832 0.083073" rpy="0 0 0"/>
  <parent link="Arm_02.step_1"/>
  <child link="Arm_03.step_1"/>
  <axis xyz="-0.200205 -0.26284 0.94384"/>
  <limit upper="6.283185" lower="0.0" effort="100" velocity="100"/>
</joint>

<joint name="Revolute_8" type="revolute">
  <origin xyz="-0.013278 -0.018969 0.034421" rpy="0 0 0"/>
  <parent link="Gripper_Base.step_1"/>
  <child link="Part_2_gear_2.step_1"/>
  <axis xyz="0.999826 0.011538 -0.014668"/>
  <limit upper="0.698132" lower="-0.558505" effort="100" velocity="100"/>
</joint>




<joint name="Revolute_24" type="revolute">
  <origin xyz="-0.010404 -0.020619 0.021718" rpy="0 0 0"/>
  <parent link="Arm_03.step_1"/>
  <child link="Gripper_Base.step_1"/>
  <axis xyz="-0.007206 0.963712 0.266845"/>
  <limit upper="1.570796" lower="-1.570796" effort="100" velocity="100"/>
</joint>

<joint name="Rigid_25" type="fixed">
  <origin xyz="-0.013472 0.006955 0.041599" rpy="0 0 0"/>
  <parent link="Gripper_Base.step_1"/>
  <child link="Servo_motor_micro_9g.step_1"/>
</joint>

<joint name="Revolute_26" type="revolute">
  <origin xyz="0.0 0.0 0.0" rpy="0 0 0"/>
  <parent link="Servo_motor_micro_9g.step_1"/>
  <child link="Part_1_gear_2.step_1"/>
  <axis xyz="-0.999826 -0.011538 0.014668"/>
  <limit upper="1.239184" lower="0.034907" effort="100" velocity="100"/>
</joint>

<joint name="Revolute_31" type="revolute">
  <origin xyz="0.000621 -0.028584 0.019863" rpy="0 0 0"/>
  <parent link="Part_2_gear_2.step_1"/>
  <child link="robot_Gripper.step1_v1_1"/>
  <axis xyz="-0.999826 -0.011538 0.014668"/>
  <limit upper="1.134464" lower="-0.645772" effort="100" velocity="100"/>
</joint>







<joint name="Revolute_42" type="continuous">
  <origin xyz="0.003126 0.001866 0.059863" rpy="0 0 0"/>
  <parent link="base_link"/>
  <child link="Waist.step_1"/>
  <axis xyz="-0.030811 -0.009585 0.999479"/>
</joint>

<joint name="Revolute_43" type="continuous">
  <origin xyz="0.009843 0.008912 0.04069" rpy="0 0 0"/>
  <parent link="Waist.step_1"/>
  <child link="Arm_01.step_1"/>
  <axis xyz="0.828979 -0.558915 0.020195"/>
</joint>

<joint name="Revolute_44" type="revolute">
  <origin xyz="0.000376 0.011475 0.03469" rpy="0 0 0"/>
  <parent link="Part_1_gear_2.step_1"/>
  <child link="Gripper.step_1"/>
  <axis xyz="0.999826 0.011538 -0.014668"/>
  <limit upper="1.204277" lower="0.0" effort="100" velocity="100"/>
</joint>

<transmission name="Revolute_42_tran">
  <type>transmission_interface/SimpleTransmission</type>
  <joint name="Revolute_42">
    <hardwareInterface>hardware_interface/PositionJointInterface</hardwareInterface>
  </joint>
  <actuator name="Revolute_42_actr">
    <hardwareInterface>hardware_interface/PositionJointInterface</hardwareInterface>
    <mechanicalReduction>1</mechanicalReduction>
  </actuator>
</transmission>

<transmission name="Revolute_4_tran">
  <type>transmission_interface/SimpleTransmission</type>
  <joint name="Revolute_4">
    <hardwareInterface>hardware_interface/PositionJointInterface</hardwareInterface>
  </joint>
  <actuator name="Revolute_4_actr">
    <hardwareInterface>hardware_interface/PositionJointInterface</hardwareInterface>
    <mechanicalReduction>1</mechanicalReduction>
  </actuator>
</transmission>

<transmission name="Revolute_5_tran">
  <type>transmission_interface/SimpleTransmission</type>
  <joint name="Revolute_5">
    <hardwareInterface>hardware_interface/PositionJointInterface</hardwareInterface>
  </joint>
  <actuator name="Revolute_5_actr">
    <hardwareInterface>hardware_interface/PositionJointInterface</hardwareInterface>
    <mechanicalReduction>1</mechanicalReduction>
  </actuator>
</transmission>

<transmission name="Revolute_8_tran">
  <type>transmission_interface/SimpleTransmission</type>
  <joint name="Revolute_8">
    <hardwareInterface>hardware_interface/PositionJointInterface</hardwareInterface>
  </joint>
  <actuator name="Revolute_8_actr">
    <hardwareInterface>hardware_interface/PositionJointInterface</hardwareInterface>
    <mechanicalReduction>1</mechanicalReduction>
  </actuator>
</transmission>



<transmission name="Revolute_24_tran">
  <type>transmission_interface/SimpleTransmission</type>
  <joint name="Revolute_24">
    <hardwareInterface>hardware_interface/PositionJointInterface</hardwareInterface>
  </joint>
  <actuator name="Revolute_24_actr">
    <hardwareInterface>hardware_interface/PositionJointInterface</hardwareInterface>
    <mechanicalReduction>1</mechanicalReduction>
  </actuator>
</transmission>

<transmission name="Revolute_26_tran">
  <type>transmission_interface/SimpleTransmission</type>
  <joint name="Revolute_26">
    <hardwareInterface>hardware_interface/PositionJointInterface</hardwareInterface>
  </joint>
  <actuator name="Revolute_26_actr">
    <hardwareInterface>hardware_interface/PositionJointInterface</hardwareInterface>
    <mechanicalReduction>1</mechanicalReduction>
  </actuator>
</transmission>





<transmission name="Revolute_31_tran">
  <type>transmission_interface/SimpleTransmission</type>
  <joint name="Revolute_31">
    <hardwareInterface>hardware_interface/PositionJointInterface</hardwareInterface>
  </joint>
  <actuator name="Revolute_31_actr">
    <hardwareInterface>hardware_interface/PositionJointInterface</hardwareInterface>
    <mechanicalReduction>1</mechanicalReduction>
  </actuator>
</transmission>

<transmission name="Revolute_44_tran">
  <type>transmission_interface/SimpleTransmission</type>
  <joint name="Revolute_44">
    <hardwareInterface>hardware_interface/PositionJointInterface</hardwareInterface>
  </joint>
  <actuator name="Revolute_44_actr">
    <hardwareInterface>hardware_interface/PositionJointInterface</hardwareInterface>
    <mechanicalReduction>1</mechanicalReduction>
  </actuator>
</transmission>







<transmission name="Revolute_42_tran">
  <type>transmission_interface/SimpleTransmission</type>
  <joint name="Revolute_42">
    <hardwareInterface>hardware_interface/PositionJointInterface</hardwareInterface>
  </joint>
  <actuator name="Revolute_42_actr">
    <hardwareInterface>hardware_interface/PositionJointInterface</hardwareInterface>
    <mechanicalReduction>1</mechanicalReduction>
  </actuator>
</transmission>

<transmission name="Revolute_43_tran">
  <type>transmission_interface/SimpleTransmission</type>
  <joint name="Revolute_43">
    <hardwareInterface>hardware_interface/PositionJointInterface</hardwareInterface>
  </joint>
  <actuator name="Revolute_43_actr">
    <hardwareInterface>hardware_interface/PositionJointInterface</hardwareInterface>
    <mechanicalReduction>1</mechanicalReduction>
  </actuator>
</transmission>


<gazebo reference="base_link">
  <material>${body_color}</material>
  <mu1>0.2</mu1>
  <mu2>0.2</mu2>
  <selfCollide>true</selfCollide>
  <gravity>true</gravity>
</gazebo>

<gazebo reference="Arm_02.step_1">
  <material>${body_color}</material>
  <mu1>0.2</mu1>
  <mu2>0.2</mu2>
  <selfCollide>true</selfCollide>
</gazebo>

<gazebo reference="Arm_03.step_1">
  <material>${body_color}</material>
  <mu1>0.2</mu1>
  <mu2>0.2</mu2>
  <selfCollide>true</selfCollide>
</gazebo>

<gazebo reference="Part_2_gear_2.step_1">
  <material>${body_color}</material>
  <mu1>0.2</mu1>
  <mu2>0.2</mu2>
  <selfCollide>true</selfCollide>
</gazebo>


<gazebo reference="Gripper_Base.step_1">
  <material>${body_color}</material>
  <mu1>0.2</mu1>
  <mu2>0.2</mu2>
  <selfCollide>true</selfCollide>
</gazebo>

<gazebo reference="Servo_motor_micro_9g.step_1">
  <material>${body_color}</material>
  <mu1>0.2</mu1>
  <mu2>0.2</mu2>
  <selfCollide>true</selfCollide>
</gazebo>

<gazebo reference="Part_1_gear_2.step_1">
  <material>${body_color}</material>
  <mu1>0.2</mu1>
  <mu2>0.2</mu2>
  <selfCollide>true</selfCollide>
</gazebo>

<gazebo reference="Gripper.step_1">
  <material>${body_color}</material>
  <mu1>0.2</mu1>
  <mu2>0.2</mu2>
  <selfCollide>true</selfCollide>
</gazebo>

<gazebo reference="Gripper.step_1">
  <material>${body_color}</material>
  <mu1>0.2</mu1>
  <mu2>0.2</mu2>
  <selfCollide>true</selfCollide>
</gazebo>

<gazebo reference="robot_Gripper.step1_v1_1">
  <material>${body_color}</material>
  <mu1>0.2</mu1>
  <mu2>0.2</mu2>
  <selfCollide>true</selfCollide>
</gazebo>



<gazebo reference="robot_Gripper.step1_v1_1">
  <material>${body_color}</material>
  <mu1>0.2</mu1>
  <mu2>0.2</mu2>
  <selfCollide>true</selfCollide>
</gazebo>

<gazebo reference="Waist.step_1">
  <material>${body_color}</material>
  <mu1>0.2</mu1>
  <mu2>0.2</mu2>
  <selfCollide>true</selfCollide>
</gazebo>

<gazebo reference="Arm_01.step_1">
  <material>${body_color}</material>
  <mu1>0.2</mu1>
  <mu2>0.2</mu2>
  <selfCollide>true</selfCollide>
</gazebo>





</robot>
